Workbook

Sheet CABEÇALHO
D1: PETERMANN & MORAIS LTDA ME - CNPJ 17.117.768/0001-42
D2: Rua Natal Vasconcelos Montes, 185 - Sala 01. Centro.
D3: CEP.: 75.503-340
D4: Itumbiara, Goiás
A5: DESPESAS CORPORATIVAS | PETERMANN & MORAIS LTDA
A6: FUNCIONÁRIO: | B6: Cleiton Queiroz
A7: SAFRA: | B7: 25/26 | H7: ANO DO EXERCÍCIO: | I7: 2026
A8: RELATÓRIO DE DESPESAS MENSAIS (RDM) E RELATÓRIO DE DESPESAS COM ALIMENTAÇÕES (RDA).

Sheet NORMAS

Sheet BANCO DE DADOS
L3: =B5 -> Cleiton Queiroz
L4: EXERCÍCIO DE | S4: ='CABEÇALHO'!I7 -> 2026
B5: ='CABEÇALHO'!B6 -> Cleiton Queiroz | I5: ='CABEÇALHO'!I7 -> 2026 | L5: Meses | M5: Janeiro | N5: Fevereiro | O5: Março | P5: Abril | Q5: Maio | R5: Junho | S5: Julho | T5: Agosto | U5: Setembro | V5: Outubro | W5: Novembro | X5: Dezembro
B6: CUSTOS TOTAIS DE RDM RECEBIDO | F6: CUSTOS TOTAIS DE RDA RECEBIDO | L6: RDM | M6: =R.D.M.!E38 -> 1016.78 | N6: =R.D.M.!E85 -> 1886.52 | O6: =R.D.M.!E132 -> 1723.43 | P6: =R.D.M.!E179 -> 1687.34 | Q6: =R.D.M.!E226 -> 1637.64 | R6: =R.D.M.!E273 -> 365.5 | S6: =R.D.M.!E320 -> 717.47 | T6: =R.D.M.!E367 -> 6546.16 | U6: =R.D.M.!E414 -> 1114.28 | V6: =R.D.M.!E461 -> 0 | W6: =R.D.M.!E508 -> 0 | X6: =R.D.M.!E555 -> 0
B7: =C95 -> 17182.07 | F7: =H27 -> 5326.66 | L7: Trimestres | M7: =SUM(M6:O6) -> 4626.73 | P7: =SUM(P6:R6) -> 3690.48 | S7: =SUM(S6:U6) -> 8377.91 | V7: =SUM(V6:X6) -> 0
B8: TOTAL DE GASTO ACUMULADO DE RDM | F8: TOTAL DE GASTO ACUMULADO DE RDA | L8: RDA | M8: =R.D.A!G21 -> 2867.73 | N8: =R.D.A!G38 -> 1634.43 | O8: =R.D.A!G55 -> 1615.48 | P8: =R.D.A!G72 -> 1676.5 | Q8: =R.D.A!G89 -> 1983.55 | R8: =R.D.A!G106 -> 447.75 | S8: =R.D.A!G123 -> 1204.1 | T8: =R.D.A!G140 -> 1076.4 | U8: =R.D.A!G157 -> 1432.63 | V8: =R.D.A!G174 -> 0 | W8: =R.D.A!G191 -> 0 | X8: =R.D.A!G208 -> 0
B9: =R.D.M.!D2 -> 16695.12 | F9: =SUM(R.D.A!G21+R.D.A!G38+R.D.A!G55+R.D.A!G72+R.D.A!G89+R.D.A!G106+R.D.A!G123+R.D.A!G140+R.D.A!G157+R.D.A!G174+R.D.A!G191+R.D.A!G208) -> 13938.57 | L9: Trimestres | M9: =SUM(M8:O8) -> 6117.64 | P9: =SUM(P8:R8) -> 4107.8 | S9: =SUM(S8:U8) -> 3713.13 | V9: =SUM(V8:X8) -> 0
B10: SALDO DE RDM RECEBIDO | F10: SALDO DE RDA RECEBIDO | L10: TOTAL/TRIM | M10: =SUM(M7,M9) -> 10744.37 | P10: =SUM(P7,P9) -> 7798.28 | S10: =SUM(S7,S9) -> 12091.04 | V10: =SUM(V7,V9) -> 0
B11: =B7-B9 -> 486.95 | F11: =F7-F9 -> -8611.91 | L11: TOTAL GERAL | M11: =SUM(M10,P10,S10,V10) -> 30633.69
B12: Inserir COM ATENÇÃO abaixo, todo o valor repassado para as despesas mensais! | F12: Inserir COM ATENÇÃO abaixo, todo o valor repassado para as despesas de aimentação!
B13: EXTRATO DE RDM RECEBIDO | F13: EXTRATO DE RDA RECEBIDO
B14: DATA | C14: R$ | F14: DATA | H14: R$
B15: 46047 | C15: 500.5 | F15: 46062 | H15: 426.66
B16: 46055 | C16: 1000 | F16: 46062 | H16: 1600
B17: 46084 | C17: 1500 | F17: 46096 | H17: 1600
B18: 46096 | C18: 700 | F18: 46121 | H18: 1700
B19: 46121 | C19: 2000
B20: 46160 | C20: 1081.57
B21: 46169 | C21: 1000
B22: 46228 | C22: 2000
B23: 46246 | C23: 1000
B24: 46252 | C24: 1400
B25: 46259 | C25: 3000
B26: 46267 | C26: 1000
B27: 46269 | C27: 1000 | F27: TOTAL | H27: =SUM(H15:H26) -> 5326.66
F28: CONSUMIDO | H28: =F9 -> 13938.57
F29: SALDO | H29: =H27-H28 -> -8611.91
B95: TOTAL | C95: =SUBTOTAL(9,C15:C94) -> 17182.07

Sheet R.D.M.
A1: ='CABEÇALHO'!B6 -> Cleiton Queiroz | B1: RELATÓRIO DE DESPESAS MENSAIS (R.D.M.) | G1: ='CABEÇALHO'!B6 -> Cleiton Queiroz | J1: ='CABEÇALHO'!I7 -> 2026
B2: TOTAL DE GASTO ACUMULADO | D2: =SUM(E38,E85,E132,E179,E226,E273,E320,E367,E414,E461,E508,E555) -> 16695.12 | E2: TOTAL RECEBIDO | G2: ='BANCO DE DADOS'!C95 -> 17182.07 | H2: SALDO | J2: =D2-G2 -> -486.95
B3: ABASTECIMENTO | E3: HOSPEDAGENS | H3: OUTROS (BORRACHARIA/OFICINA/EPI'S)
B4: DATA | C4: CNPJ DA NOTA | D4: R$ | E4: DATA | F4: CNPJ DA NOTA | G4: R$ | H4: DATA | I4: CNPJ DA NOTA | J4: R$
B5: JANEIRO | E5: JANEIRO | H5: JANEIRO
B6: 46030 | C6: 31.747832/0001-08 | D6: 181.27 | E6: 46047 | F6: 41.724.044/0001-41 | G6: 162 | H6: 46029 | I6: 62.037.020/0001-94 | J6: 140
B7: 46047 | C7: 50.779.798/0001-90 | D7: 200.02 | H7: 46048 | I7: 46.379.964/0001-93 | J7: 41
B8: 46049 | C8: 40.579.530/0001-79 | D8: 292.49
B37: TOTAL DE GASTOS | D37: =SUM(D6:D36) -> 673.78 | E37: TOTAL DE GASTOS | G37: =SUM(G6:G36) -> 162 | H37: TOTAL DE GASTOS | J37: =SUM(J6:J36) -> 181
E38: =SUM(D37,G37,J37) -> 1016.78
B39: FEVEREIRO | E39: FEVEREIRO | H39: FEVEREIRO
B40: 46055 | C40: 18.645.018/0001-06 | D40: 245.12 | H40: 46065 | I40: 01.138.122/0001-01 | J40: 50
B41: 46059 | C41: 18.645.018/0001-06 | D41: 170.02 | H41: 46074 | I41: RECIBO | J41: 60
B42: 46064 | C42: 18.645.018/0001-06 | D42: 168.02 | H42: 46078 | I42: 21.938.486/0001-83 | J42: 133.6
B43: 46065 | C43: 01.330.605/0001-03 | D43: 50 | H43: 46108 | I43: 65.132.211/0001-23 | J43: 60
B44: 46067 | C44: 18.645.018/0001-03 | D44: 349.68
B45: 46073 | C45: 13.615.307/0001-49 | D45: 303.08
B46: 46080 | C46: 29.275.106/0001-80 | D46: 297
B84: TOTAL DE GASTOS | D84: =SUM(D40:D83) -> 1582.92 | E84: TOTAL DE GASTOS | G84: =SUM(G40:G83) -> 0 | H84: TOTAL DE GASTOS | J84: =SUM(J40:J83) -> 303.6
E85: =SUM(D84,G84,J84) -> 1886.52
B86: MARÇO | E86: MARÇO | H86: MARÇO
H87: 46095 | I87: 35.856.131/0001-50 | J87: 150
B88: 46084 | C88: 03.747.723/0001-47 | D88: 291.42 | H88: 46096 | I88: pagamento via Pix serviço de limpeza do quintal | J88: 250
B89: 46086 | C89: 31.74940/00001-65 | D89: 100 | H89: 46096 | I89: 21.938.486/0001-83 | J89: 71
B90: 46111 | C90: 07.760.547/0001-34 | D90: 331.53 | H90: 46097 | I90: recibo | J90: 70
H91: 46102 | I91: 37.219.093/0001-50 | J91: 148.11
H92: 46102 | I92: 05.705.338/0001-62 | J92: 71.37
H93: 46083 | I93: 54.738.731/0001-68 | J93: 180
H94: 46108 | I94: recibo | J94: 60
B131: TOTAL DE GASTOS | D131: =SUM(D87:D130) -> 722.95 | E131: TOTAL DE GASTOS | G131: =SUM(G87:G130) -> 0 | H131: TOTAL DE GASTOS | J131: =SUM(J87:J130) -> 1000.48
E132: =SUM(D131,G131,J131) -> 1723.43
B133: ABRIL | E133: ABRIL | H133: ABRIL
B134: 46131 | C134: 42.057.303/0001-90 | D134: 50 | H134: 46113 | I134: 00.487.954/0001-42 | J134: 981
H135: 46113 | I135: 00.487.954/0001-42 | J135: 162
H136: 46120 | I136: 21.938.486/0001-83 | J136: 82.18
H137: 46120 | I137: 21.938.486/0001-83 | J137: 29.3
H138: 46125 | I138: 05.705.338/0001-62 | J138: 53.18
H139: 46130 | I139: 39.363.721/0001-00 | J139: 159.7
H140: 46133 | I140: 17.457.404/0007-05 | J140: 119.98
H141: 46135 | I141: 65.132.211/0001-23 | J141: 50
...

Sheet R.D.A
A1: ='CABEÇALHO'!B6 -> Cleiton Queiroz | B1: RELATÓRIO DE DESPESAS COM ALIMENTAÇÕES (R.D.A.) | F1: ='CABEÇALHO'!B6 -> Cleiton Queiroz
B4: JANEIRO | E4: ='CABEÇALHO'!I7 -> 2026
B5: DATA | C5: CNPJ | D5: R$ | E5: DATA | F5: CNPJ | G5: R$
B6: 46024 | C6: 05.764.979/0001-98 | D6: 61.5 | E6: 46024 | F6: 05.764.979/0001-98 | G6: 48
B7: 46024 | C7: 05.764.979/0001-98 | D7: 161.8 | E7: 46024 | F7: 05.764.979/0001-98 | G7: 183.5
B8: 46024 | C8: 05.764.979/0001-98 | D8: 98 | E8: 46024 | F8: 05.764.979/0001-98 | G8: 154
B9: 46024 | C9: 05.764.979/0001-98 | D9: 100.87 | E9: 46024 | F9: 05.764.979/0001-98 | G9: 215.4
B10: 46024 | C10: 05.764.979/0001-98 | D10: 191.9 | E10: 46024 | F10: 05.764.979/0001-98 | G10: 114
B11: 46024 | C11: 05.764.979/0001-98 | D11: 164.4
B12: 46024 | C12: 05.764.979/0001-98 | D12: 174.6
B13: 46024 | C13: 05.764.979/0001-98 | D13: 64
B14: 46024 | C14: 05.764.979/0001-98 | D14: 144.36
B15: 46024 | C15: 05.764.979/0001-98 | D15: 101.5
B16: 46024 | C16: 05.764.979/0001-98 | D16: 224.4
B17: 46024 | C17: 05.764.979/0001-98 | D17: 167
B18: 46024 | C18: 05.764.979/0001-98 | D18: 231.5
B19: 46024 | C19: 05.764.979/0001-98 | D19: 190
B20: 46024 | C20: 05.764.979/0001-98 | D20: 77
G21: =SUM(D6:D20,G6:G20) -> 2867.73
B22: FEVEREIRO | E22: ='CABEÇALHO'!I7 -> 2026
B23: Data | C23: CNPJ | D23: Valor Total (R$)
B24: 46064 | C24: 05.754.979/0001-98 | D24: 208.55
B25: 46064 | C25: 05.754.979/0001-98 | D25: 38
B26: 46063 | C26: 05.754.979/0001-98 | D26: 273.65
B27: 46065 | C27: 05.754.979/0001-98 | D27: 298
B28: 46065 | C28: 05.754.979/0001-98 | D28: 258.4
B29: 46063 | C29: 05.754.979/0001-98 | D29: 231.9
B30: 46063 | C30: 05.754.979/0001-98 | D30: 220.8
B31: 46057 | C31: 07.363.173/0001-13 | D31: 64.72
B32: 46063 | C32: 07.363.173/0001-13 | D32: 40.41
G38: =SUM(D23:D37,G23:G37) -> 1634.43
B39: MARÇO | E39: ='CABEÇALHO'!I7 -> 2026
B40: 21/03/2026 | C40: 05.705.338/0001-62 | D40: 71.37
B41: 21/03/2026 | C41: 37.219.093/0001-50 | D41: 148.11
B42: 23/03/2026 | C42: 05.764.979/0001-98 | D42: 172.7
B43: 23/03/2026 | C43: 05.764.979/0001-98 | D43: 143.7
B44: 23/03/2026 | C44: 05.764.979/0001-98 | D44: 137.3
B45: 23/03/2026 | C45: 05.764.979/0001-98 | D45: 126.2
B46: 23/03/2026 | C46: 05.764.979/0001-98 | D46: 102.95
B47: 23/03/2026 | C47: 05.764.979/0001-98 | D47: 224.7
...
